<?xml version="1.0" encoding="UTF-8"?>
<!-- Generated by org.testng.reporters.JUnitReportReporter -->
<testsuite hostname="asd-PC" name="com.anupam.testngex.TestCalculator3" tests="3" failures="0" timestamp="2 Oct 2013 12:48:49 GMT" time="20.115" errors="2">
  <testcase name="longLoopFailTest" time="0.023" classname="com.anupam.testngex.TestCalculator3">
    <error type="org.testng.internal.thread.ThreadTimeoutException" message="Method org.testng.internal.TestNGMethod.longLoopFailTest() didn&#039;t finish within the time-out 10">
      <![CDATA[org.testng.internal.thread.ThreadTimeoutException: Method org.testng.internal.TestNGMethod.longLoopFailTest() didn't finish within the time-out 10
	at java.lang.System.arraycopy(Native Method)
	at java.io.BufferedOutputStream.write(Unknown Source)
	at java.io.PrintStream.write(Unknown Source)
	at sun.nio.cs.StreamEncoder.writeBytes(Unknown Source)
	at sun.nio.cs.StreamEncoder.implFlushBuffer(Unknown Source)
	at sun.nio.cs.StreamEncoder.flushBuffer(Unknown Source)
	at java.io.OutputStreamWriter.flushBuffer(Unknown Source)
	at java.io.PrintStream.write(Unknown Source)
	at java.io.PrintStream.print(Unknown Source)
	at com.anupam.testngex.Calculator.longLoop(Calculator.java:56)
	at com.anupam.testngex.TestCalculator3.longLoopFailTest(TestCalculator3.java:28)
	at sun.reflect.NativeMethodAccessorImpl.invoke0(Native Method)
	at sun.reflect.NativeMethodAccessorImpl.invoke(Unknown Source)
	at sun.reflect.DelegatingMethodAccessorImpl.invoke(Unknown Source)
	at java.lang.reflect.Method.invoke(Unknown Source)
	at org.testng.internal.MethodInvocationHelper.invokeMethod(MethodInvocationHelper.java:74)
	at org.testng.internal.InvokeMethodRunnable.runOne(InvokeMethodRunnable.java:46)
	at org.testng.internal.InvokeMethodRunnable.run(InvokeMethodRunnable.java:37)
	at java.util.concurrent.Executors$RunnableAdapter.call(Unknown Source)
	at java.util.concurrent.FutureTask$Sync.innerRun(Unknown Source)
	at java.util.concurrent.FutureTask.run(Unknown Source)
	at java.util.concurrent.ThreadPoolExecutor.runWorker(Unknown Source)
	at java.util.concurrent.ThreadPoolExecutor$Worker.run(Unknown Source)
	at java.lang.Thread.run(Unknown Source)
]]>
    </error>
  </testcase>
  <testcase name="seeExceptionTest" time="0.005" classname="com.anupam.testngex.TestCalculator3">
    <error type="java.lang.ArrayIndexOutOfBoundsException" message="2">
      <![CDATA[java.lang.ArrayIndexOutOfBoundsException: 2
	at com.anupam.testngex.Calculator.seeException(Calculator.java:51)
	at com.anupam.testngex.TestCalculator3.seeExceptionTest(TestCalculator3.java:21)
	at sun.reflect.NativeMethodAccessorImpl.invoke0(Native Method)
	at sun.reflect.NativeMethodAccessorImpl.invoke(Unknown Source)
	at sun.reflect.DelegatingMethodAccessorImpl.invoke(Unknown Source)
	at java.lang.reflect.Method.invoke(Unknown Source)
	at org.testng.internal.MethodInvocationHelper.invokeMethod(MethodInvocationHelper.java:74)
	at org.testng.internal.Invoker.invokeMethod(Invoker.java:674)
	at org.testng.internal.Invoker.invokeTestMethod(Invoker.java:847)
	at org.testng.internal.Invoker.invokeTestMethods(Invoker.java:1152)
	at org.testng.internal.TestMethodWorker.invokeTestMethods(TestMethodWorker.java:137)
	at org.testng.internal.TestMethodWorker.run(TestMethodWorker.java:121)
	at org.testng.TestRunner.runWorkers(TestRunner.java:1119)
	at org.testng.TestRunner.privateRun(TestRunner.java:744)
	at org.testng.TestRunner.run(TestRunner.java:600)
	at org.testng.SuiteRunner.runTest(SuiteRunner.java:315)
	at org.testng.SuiteRunner.runSequentially(SuiteRunner.java:310)
	at org.testng.SuiteRunner.privateRun(SuiteRunner.java:272)
	at org.testng.SuiteRunner.run(SuiteRunner.java:221)
	at org.testng.SuiteRunnerWorker.runSuite(SuiteRunnerWorker.java:52)
	at org.testng.SuiteRunnerWorker.run(SuiteRunnerWorker.java:86)
	at org.testng.TestNG.runSuitesSequentially(TestNG.java:952)
	at org.testng.TestNG.runSuitesLocally(TestNG.java:889)
	at org.testng.TestNG.run(TestNG.java:818)
	at org.testng.remote.RemoteTestNG.run(RemoteTestNG.java:89)
	at org.testng.remote.RemoteTestNG.main(RemoteTestNG.java:144)
]]>
    </error>
  </testcase>
  <testcase name="longLoopPassTest" time="20.087" classname="com.anupam.testngex.TestCalculator3">
    <error type="org.testng.internal.thread.ThreadTimeoutException" message="Method org.testng.internal.TestNGMethod.longLoopPassTest() didn&#039;t finish within the time-out 20000">
      <![CDATA[org.testng.internal.thread.ThreadTimeoutException: Method org.testng.internal.TestNGMethod.longLoopPassTest() didn't finish within the time-out 20000
	at java.io.PrintStream.write(Unknown Source)
	at java.io.PrintStream.print(Unknown Source)
	at com.anupam.testngex.Calculator.longLoop(Calculator.java:56)
	at com.anupam.testngex.TestCalculator3.longLoopPassTest(TestCalculator3.java:35)
	at sun.reflect.NativeMethodAccessorImpl.invoke0(Native Method)
	at sun.reflect.NativeMethodAccessorImpl.invoke(Unknown Source)
	at sun.reflect.DelegatingMethodAccessorImpl.invoke(Unknown Source)
	at java.lang.reflect.Method.invoke(Unknown Source)
	at org.testng.internal.MethodInvocationHelper.invokeMethod(MethodInvocationHelper.java:74)
	at org.testng.internal.InvokeMethodRunnable.runOne(InvokeMethodRunnable.java:46)
	at org.testng.internal.InvokeMethodRunnable.run(InvokeMethodRunnable.java:37)
	at java.util.concurrent.Executors$RunnableAdapter.call(Unknown Source)
	at java.util.concurrent.FutureTask$Sync.innerRun(Unknown Source)
	at java.util.concurrent.FutureTask.run(Unknown Source)
	at java.util.concurrent.ThreadPoolExecutor.runWorker(Unknown Source)
	at java.util.concurrent.ThreadPoolExecutor$Worker.run(Unknown Source)
	at java.lang.Thread.run(Unknown Source)
]]>
    </error>
  </testcase>
</testsuite>
