<?xml version="1.0" encoding="UTF-8"?>
<testsuite hostname="asd-PC" name="com.anupam.testngex.TestCalculator3" tests="3" failures="2" timestamp="2 Oct 2013 12:45:43 GMT" time="20.3" errors="0">
  <testcase name="longLoopFailTest" time="0.023" classname="com.anupam.testngex.TestCalculator3">
    <failure type="org.testng.internal.thread.ThreadTimeoutException" message="Method org.testng.internal.TestNGMethod.longLoopFailTest() didn&amp;apos;t finish within the time-out 10">
      <![CDATA[org.testng.internal.thread.ThreadTimeoutException: Method org.testng.internal.TestNGMethod.longLoopFailTest() didn't finish within the time-out 10
	at java.lang.System.arraycopy(Native Method)
	at java.io.BufferedOutputStream.write(Unknown Source)
	at java.io.PrintStream.write(Unknown Source)
	at sun.nio.cs.StreamEncoder.writeBytes(Unknown Source)
	at sun.nio.cs.StreamEncoder.implFlushBuffer(Unknown Source)
	at sun.nio.cs.StreamEncoder.flushBuffer(Unknown Source)
	at java.io.OutputStreamWriter.flushBuffer(Unknown Source)
	at java.io.PrintStream.write(Unknown Source)
	at java.io.PrintStream.print(Unknown Source)
	at com.anupam.testngex.Calculator.longLoop(Calculator.java:56)
	at com.anupam.testngex.TestCalculator3.longLoopFailTest(TestCalculator3.java:28)
	at sun.reflect.NativeMethodAccessorImpl.invoke0(Native Method)
	at sun.reflect.NativeMethodAccessorImpl.invoke(Unknown Source)
	at sun.reflect.DelegatingMethodAccessorImpl.invoke(Unknown Source)
	at java.lang.reflect.Method.invoke(Unknown Source)
	at org.testng.internal.MethodInvocationHelper.invokeMethod(MethodInvocationHelper.java:74)
	at org.testng.internal.InvokeMethodRunnable.runOne(InvokeMethodRunnable.java:46)
	at org.testng.internal.InvokeMethodRunnable.run(InvokeMethodRunnable.java:37)
	at java.util.concurrent.Executors$RunnableAdapter.call(Unknown Source)
	at java.util.concurrent.FutureTask$Sync.innerRun(Unknown Source)
	at java.util.concurrent.FutureTask.run(Unknown Source)
	at java.util.concurrent.ThreadPoolExecutor.runWorker(Unknown Source)
	at java.util.concurrent.ThreadPoolExecutor$Worker.run(Unknown Source)
	at java.lang.Thread.run(Unknown Source)
]]>
    </failure>
  </testcase>
  <testcase name="longLoopPassTest" time="20.087" classname="com.anupam.testngex.TestCalculator3">
    <failure type="org.testng.internal.thread.ThreadTimeoutException" message="Method org.testng.internal.TestNGMethod.longLoopPassTest() didn&amp;apos;t finish within the time-out 20000">
      <![CDATA[org.testng.internal.thread.ThreadTimeoutException: Method org.testng.internal.TestNGMethod.longLoopPassTest() didn't finish within the time-out 20000
	at java.io.PrintStream.write(Unknown Source)
	at java.io.PrintStream.print(Unknown Source)
	at com.anupam.testngex.Calculator.longLoop(Calculator.java:56)
	at com.anupam.testngex.TestCalculator3.longLoopPassTest(TestCalculator3.java:35)
	at sun.reflect.NativeMethodAccessorImpl.invoke0(Native Method)
	at sun.reflect.NativeMethodAccessorImpl.invoke(Unknown Source)
	at sun.reflect.DelegatingMethodAccessorImpl.invoke(Unknown Source)
	at java.lang.reflect.Method.invoke(Unknown Source)
	at org.testng.internal.MethodInvocationHelper.invokeMethod(MethodInvocationHelper.java:74)
	at org.testng.internal.InvokeMethodRunnable.runOne(InvokeMethodRunnable.java:46)
	at org.testng.internal.InvokeMethodRunnable.run(InvokeMethodRunnable.java:37)
	at java.util.concurrent.Executors$RunnableAdapter.call(Unknown Source)
	at java.util.concurrent.FutureTask$Sync.innerRun(Unknown Source)
	at java.util.concurrent.FutureTask.run(Unknown Source)
	at java.util.concurrent.ThreadPoolExecutor.runWorker(Unknown Source)
	at java.util.concurrent.ThreadPoolExecutor$Worker.run(Unknown Source)
	at java.lang.Thread.run(Unknown Source)
]]>
    </failure>
  </testcase>
  <testcase name="seeExceptionTest" time="0.005" classname="com.anupam.testngex.TestCalculator3"/>
</testsuite>
